Workbook

Sheet July 2023 
A1: Monthly Budget - July 2023
A4: Monthly Spending | G4: Monthly Overview | J4: Expenses over Time
A5: Category | B5: Budgeted | C5: Amount Spent | D5: Amount Remaining | E5: % Remaining | G5: Income
A6: Fixed | B6: 2500 | C6: =sumif($B$20:$C$100,A6,$C$20:$C$100) -> 2663.68 | D6: =B6-C6 -> -163.68 | E6: =D6/B6 -> -0.065472 | G6: Martin Paycheck | H6: ='MartinRachel Pay Stub'!B20*2 -> 3851.86
A7: Utilities | B7: 0 | C7: =sumif($B$20:$C$100,A7,$C$20:$C$100) -> 0 | D7: =B7-C7 -> 0 | E7: =D7/B7 -> #DIV/0! | G7: Rachel Paycheck | H7: ='MartinRachel Pay Stub'!E20*2 -> 5429.1
A8: Bills | B8: 250 | C8: =sumif($B$20:$C$100,A8,$C$20:$C$100) -> 413.77 | D8: =B8-C8 -> -163.77 | E8: =D8/B8 -> -0.65508
A9: Groceries | B9: 400 | C9: =sumif($B$20:$C$100,A9,$C$20:$C$100) -> 925.9 | D9: =B9-C9 -> -525.9 | E9: =D9/B9 -> -1.31475 | G9: Monthly Expenses
A10: Eating out | B10: 400 | C10: =sumif($B$20:$C$100,A10,$C$20:$C$100) -> 331.56 | D10: =B10-C10 -> 68.44 | E10: =D10/B10 -> 0.1711 | G10: Total Spent | H10: =sum(C16) -> 5549.63
A11: Household Goods | B11: 200 | C11: =sumif($B$20:$C$100,A11,$C$20:$C$100) -> 207.32 | D11: =B11-C11 -> -7.32 | E11: =D11/B11 -> -0.0366
A12: Travel Fund | B12: 500 | C12: 500 | D12: =B12-C12 -> 0 | E12: =D12/B12 -> 0 | G12: Recurring Expenses
A13: Gas | B13: 200 | C13: =sumif($B$20:$C$100,A13,$C$20:$C$100) -> 180.55 | D13: =B13-C13 -> 19.45 | E13: =D13/B13 -> 0.09725 | G13: Car Insurance
A14: Health | B14: 0 | D14: =B14-C14 -> 0 | E14: =D14/B14 -> #DIV/0!
A15: Fun / Misc | B15: 300 | C15: =sumif($B$20:$C$100,A15,$C$20:$C$100) -> 326.85 | D15: =B15-C15 -> -26.85 | E15: =D15/B15 -> -0.0895 | G15: Amount spent on Travel | H15: 0
A16: Total | B16: =SUM(B6:B15) -> 4750 | C16: =SUM(C6:C15) -> 5549.63 | D16: =SUM(D6:D15) -> -799.63 | E16: =D16/B16 -> -0.16834316 | G16: Amount in Travel Bank | H16: =500-SUMIF($B$20:$C$122,A12,$C$20:$C$122)+'July 2023 '!H15 -> 500
A19: Date | B19: Category | C19: Spent | D19: Note
A20: Monthly | B20: Fixed | C20: 2060 | D20: Rent
A21: Monthly | B21: Fixed | C21: 55 | D21: Internet
A22: Monthly | B22: Fixed | C22: 71.64 | D22: Electric
A23: Monthly | B23: Fixed | C23: 129.33 | D23: Exercise
A24: Monthly | B24: Fixed | C24: $9,86 | D24: Water
A25: Monthly | B25: Fixed | C25: =1133.34/6 -> 188.89 | D25: Car Insurance
A26: Monthly | B26: Fixed | C26: 2.87 | D26: Spotify - Martin
A27: Monthly | B27: Fixed | C27: 1.99 | D27: Google One
A28: Monthly | B28: Fixed | C28: 5.83 | D28: One Drive
A29: Monthly | B29: Fixed | C29: 148.13 | D29: Phone
A32: 45110 | B32: Bills | C32: 328.24 | D32: Car Registration
A33: 45110 | B33: Household Goods | C33: 90.28 | D33: Amazon Lamp
A34: 45110 | B34: Household Goods | C34: 2.89 | D34: phone case
A35: 45110 | B35: Gas | C35: 30 | D35: Rachel Gas
A36: 45110 | B36: Groceries | C36: 101.32 | D36: Costco
A37: 45110 | B37: Eating out | C37: 123.24 | D37: Kbbq with jiaqi
A38: 45109 | B38: Groceries | C38: 119.31 | D38: H mart
A39: 45108 | B39: Eating out | C39: 4.87 | D39: blk dog
A40: 45112 | B40: Fun / Misc | C40: 108 | D40: Gift for Martin's Mum
A41: 45115 | B41: Fun / Misc | C41: 103.97 | D41: Science Lab Donation
A42: 45115 | B42: Groceries | C42: 124.75 | D42: Costco
A43: 45115 | B43: Eating out | C43: 11.52 | D43: Costco food court
... A74: 45138 | B74: Eating out | C74: 17.4 | D74: Uber eats

Sheet Aug 2023
A4: Monthly Spending | G4: Monthly Overview | J4: Expenses over Time
A5: Category | B5: Budgeted | C5: Amount Spent | D5: Amount Remaining | E5: % Remaining | G5: Income
A6: Fixed | B6: 2663.68 | C6: =sumif($B$20:$C$122,A6,$C$20:$C$122) -> 2592.04 | D6: =B6-C6 -> 71.64 | E6: =D6/B6 -> 0.026895123 | G6: Martin Paycheck | H6: ='MartinRachel Pay Stub'!B20*2 -> 3851.86
A7: Utilities | B7: 0 | C7: =sumif($B$20:$C$122,A7,$C$20:$C$122) -> 0 | D7: =B7-C7 -> 0 | E7: =D7/B7 -> #DIV/0! | G7: Rachel Paycheck | H7: =2763*2 -> 5526
A8: Bills | B8: 250 | C8: =sumif($B$20:$C$122,A8,$C$20:$C$122) -> 86.59 | D8: =B8-C8 -> 163.41 | E8: =D8/B8 -> 0.65364
A9: Groceries | B9: 400 | C9: =sumif($B$20:$C$122,A9,$C$20:$C$122) -> 612.84 | D9: =B9-C9 -> -212.84 | E9: =D9/B9 -> -0.5321 | G9: Monthly Expenses
A10: Eating out | B10: 400 | C10: =sumif($B$20:$C$122,A10,$C$20:$C$122) -> 372.62 | D10: =B10-C10 -> 27.38 | E10: =D10/B10 -> 0.06845 | G10: Total Spent | H10: =sum(C16) -> 5352.45
A11: Household Goods | B11: 200 | C11: =sumif($B$20:$C$122,A11,$C$20:$C$122) -> 731.3 | D11: =B11-C11 -> -531.3 | E11: =D11/B11 -> -2.6565
A12: Travel | B12: 500 | C12: 500 | D12: =B12-C12 -> 0 | E12: =D12/B12 -> 0 | G12: Recurring Expenses
A13: Gas | B13: 200 | C13: =sumif($B$20:$C$122,A13,$C$20:$C$122) -> 126.23 | D13: =B13-C13 -> 73.77 | E13: =D13/B13 -> 0.36885 | G13: Car Insurance
A14: Health | B14: 0 | C14: =sumif($B$20:$C$122,A14,$C$20:$C$122) -> 23.85 | D14: =B14-C14 -> -23.85 | E14: =D14/B14 -> #DIV/0!
A15: Fun / Misc | B15: 300 | C15: =sumif($B$20:$C$122,A15,$C$20:$C$122) -> 306.98 | D15: =B15-C15 -> -6.98 | E15: =D15/B15 -> -0.023266667 | G15: Amount spent on Travel | H15: =SUMIF($B$20:$C$122,$A$12,$C$20:$C$122) -> 253.6
A16: Total | B16: =SUM(B6:B15) -> 4913.68 | C16: =SUM(C6:C15) -> 5352.45 | D16: =SUM(D6:D15) -> -438.77 | E16: =D16/B16 -> -0.089295599 | G16: Amount in Travel Bank | H16: =500-SUMIF($B$20:$C$122,A12,$C$20:$C$122)+'July 2023 '!H16 -> 746.4
A19: Date | B19: Category | C19: Spent | D19: Note
A20: Monthly | B20: Fixed | C20: 2060 | D20: Rent
A21: Monthly | B21: Fixed | C21: 55 | D21: Internet
A22: Monthly | B22: Fixed | C22: 0 | D22: Electric
A23: Monthly | B23: Fixed | C23: 129.33 | D23: Exercise
A24: Monthly | B24: Fixed | C24: $9,86 | D24: Water
A25: Monthly | B25: Fixed | C25: =1133.34/6 -> 188.89 | D25: Car Insurance
A26: Monthly | B26: Fixed | C26: 2.87 | D26: Spotify - Martin
A27: Monthly | B27: Fixed | C27: 1.99 | D27: Google One
A28: Monthly | B28: Fixed | C28: 5.83 | D28: One Drive
A29: Monthly | B29: Fixed | C29: 148.13 | D29: Phone
A32: 45139 | B32: Fun / Misc | C32: 60.62 | D32: Sephora
A33: 45139 | B33: Fun / Misc | C33: 27.04 | D33: Amazon makeup
A34: 45141 | B34: Gas | C34: 33.17 | D34: Gas
A35: 45141 | B35: Household Goods | C35: 70 | D35: Facecremas
A36: 45141 | B36: Groceries | C36: 123 | D36: Costco
A37: 45141 | B37: Health | C37: 10.87 | D37: Amazon
A38: 45142 | B38: Eating out | C38: 61.48 | D38: Truth BBQ
A39: 45143 | B39: Household Goods | C39: 155.87 | D39: WHBM -rsb
A40: 45143 | B40: Household Goods | C40: 119.06 | D40: Madewell - RSB
A41: 45143 | B41: Household Goods | C41: =214.89+96.34 -> 311.23 | D41: Club Monaco - RSB
A42: 45143 | B42: Eating out | C42: 16.72 | D42: Raising canes
A43: 45143 | B43: Fun / Misc | C43: 40.46 | D43: Gift for Eun & John
A44: 45144 | B44: Groceries | C44: 30.8 | D44: costco
A45: 45144 | B45: Groceries | C45: 82.01 | D45: central market
A46: 45147 | B46: Fun / Misc | C46: 10 | D46: Sprinkles cupcake
A47: 45147 | B47: Fun / Misc | C47: 44.19 | D47: Hatch Chiles
...

Sheet Sept 2023
A4: Monthly Spending | G4: Monthly Overview | J4: Expenses over Time
A5: Category | B5: Budgeted | C5: Amount Spent | D5: Amount Remaining | E5: % Remaining | G5: Income
A6: Fixed | B6: 2663.68 | C6: =sumif($B$20:$C$101,A6,$C$20:$C$101) -> 2620.38 | D6: =B6-C6 -> 43.3 | E6: =D6/B6 -> 0.016255706 | G6: Martin Paycheck | H6: 3643
A7: Utilities | B7: 0 | C7: =sumif($B$20:$C$101,A7,$C$20:$C$101) -> 0 | D7: =B7-C7 -> 0 | E7: =D7/B7 -> #DIV/0! | G7: Rachel Paycheck | H7: =2763*2 -> 5526
A8: Bills | B8: 250 | C8: =sumif($B$20:$C$101,A8,$C$20:$C$101) -> 0 | D8: =B8-C8 -> 250 | E8: =D8/B8 -> 1
A9: Groceries | B9: 400 | C9: =sumif($B$20:$C$101,A9,$C$20:$C$101) -> 764.92 | D9: =B9-C9 -> -364.92 | E9: =D9/B9 -> -0.9123 | G9: Monthly Expenses
A10: Eating out | B10: 400 | C10: =sumif($B$20:$C$101,A10,$C$20:$C$101) -> 461.29 | D10: =B10-C10 -> -61.29 | E10: =D10/B10 -> -0.153225 | G10: Total Spent | H10: =sum(C16) -> 5661.46
A11: Household Goods | B11: 200 | C11: =sumif($B$20:$C$101,A11,$C$20:$C$101) -> 213.2 | D11: =B11-C11 -> -13.2 | E11: =D11/B11 -> -0.066
A12: Travel | B12: 500 | C12: 500 | D12: =B12-C12 -> 0 | E12: =D12/B12 -> 0 | G12: Recurring Expenses
A13: Gas | B13: 200 | C13: =sumif($B$20:$C$101,A13,$C$20:$C$101) -> 124.48 | D13: =B13-C13 -> 75.52 | E13: =D13/B13 -> 0.3776 | G13: Car Insurance
A14: Health | B14: 0 | C14: =sumif($B$20:$C$101,A14,$C$20:$C$101) -> 39.39 | D14: =B14-C14 -> -39.39 | E14: =D14/B14 -> #DIV/0!
A15: Fun / Misc | B15: 300 | C15: =sumif($B$20:$C$101,A15,$C$20:$C$101) -> 937.8 | D15: =B15-C15 -> -637.8 | E15: =D15/B15 -> -2.126 | G15: Amount spent on Travel | H15: =SUMIF($B$20:$C$123,$A$12,$C$20:$C$123) -> 20.6
A16: Total | B16: =SUM(B6:B15) -> 4913.68 | C16: =SUM(C6:C15) -> 5661.46 | D16: =SUM(D6:D15) -> -747.78 | E16: =D16/B16 -> -0.15218329 | G16: Amount in Travel Bank | H16: =500-SUMIF($B$20:$C$123,A12,$C$20:$C$123)+'Aug 2023'!H16 -> 1225.8
A19: Date | B19: Category | C19: Spent | D19: Note
A20: Monthly | B20: Fixed | C20: 2060 | D20: Rent
A21: Monthly | B21: Fixed | C21: 0 | D21: Internet
A22: Monthly | B22: Fixed | C22: 93.34 | D22: Electric
A23: Monthly | B23: Fixed | C23: 129.33 | D23: Exercise
A24: Monthly | B24: Fixed | C24: $9,86 | D24: Water
A25: Monthly | B25: Fixed | C25: =1133.34/6 -> 188.89 | D25: Car Insurance
A26: Monthly | B26: Fixed | C26: 2.87 | D26: Spotify - Martin
A27: Monthly | B27: Fixed | C27: 1.99 | D27: Google One
A28: Monthly | B28: Fixed | C28: 5.83 | D28: One Drive
A29: Monthly | B29: Fixed | C29: 138.13 | D29: Phone
A32: 45170 | B32: Eating out | C32: 72 | D32: Kim son
A33: 45170 | B33: Gas | C33: 45 | D33: Sam's club
A34: 45170 | B34: Eating out | C34: 5.9 | D34: Coffee
A35: 45171 | B35: Eating out | C35: $53,66 | D35: Aka Sushi
A36: 45171 | B36: Groceries | C36: 17.74 | D36: Hmart
A37: 45171 | B37: Eating Out | C37: 29.06 | D37: San Dong
A38: 45171 | B38: Groceries | C38: 8.71 | D38: HEB
A39: 45171 | B39: Eating out | C39: 9.34 | D39: Torchy's Tacos
A40: 45171 | B40: Eating out | C40: 5.68 | D40: Coco Crepes
A41: 45171 | B41: Fun / Misc | C41: 36 | D41: Birthday Cake
A42: 45171 | B42: Groceries | C42: 163.17 | D42: Costco
A43: 45171 | B43: Household Goods | C43: 21 | D43: Pillow
A44: 45172 | B44: Fun / Misc | C44: 127 | D44: rachel bday
A45: 45172 | B45: Household Goods | C45: 150 | D45: Kitchenaid
A46: 45174 | B46: Household Goods | C46: 19.99 | D46: Air Filter
A47: 45172 | B47: Eating out | C47: 24.9 | D47: Luna's
...

Sheet Multiyear Plan
AI2: New Placeoff Option | AQ2: Quit Cutoff
H3: Month 1 | I3: Month 2 | J3: Month 3 | K3: Month 4 | L3: Month 5 | M3: Month 6 | N3: Month 7 | O3: Month 8 | P3: Month 9 | Q3: Month 10 | R3: Month 11 | S3: Month 12 | T3: Month 13 | U3: Month 14 | V3: Month 15 | W3: Month 16 | X3: Month 17 | Y3: Month 18 | Z3: Month 19 | AA3: Month 20 | AB3: Month 21 | AC3: Month 22 | AD3: Month 23 | AE3: Month 24 | AF3: Month 25 | AG3: Month 26 | AH3: Month 27 | AI3: Month 28 | AJ3: Month 29 | AK3: Month 30 | AL3: Month 31 | AM3: Month 32 | AN3: Month 33 | AO3: Month 34 | AP3: Month 35 | AQ3: Month 36
B4: 45323 | C4: 45352 | D4: 45383 | E4: 45413 | F4: 45444 | G4: 45474 | H4: 45505 | I4: 45536 | J4: 45566 | K4: 45597 | L4: 45627 | M4: 45658 | N4: 45689 | O4: 45717 | P4: 45748 | Q4: 45778 | R4: 45809 | S4: 45839 | T4: 45870 | U4: 45901 | V4: 45931 | W4: 45962 | X4: 45992 | Y4: 46023 | Z4: 46054 | AA4: 46082 | AB4: 46113 | AC4: 46143 | AD4: 46174 | AE4: 46204 | AF4: 46235 | AG4: 46266 | AH4: 46296 | AI4: 46327 | AJ4: 46357 | AK4: 46388 | AL4: 46419 | AM4: 46447 | AN4: 46478 | AO4: 46508 | AP4: 46539 | AQ4: 46569
A5: Rachel | C5: Rotation 2 Start | J5: R2 End | K5: Rotation 3 Start | R5: R3 End | S5: PO 1 | T5: PO2 | U5: PO 3 | V5: PO 4 | W5: PO 5 | X5: PO 6 | Y5: PO 7 | Z5: PO 8 | AA5: PO 9 | AB5: PO 10 | AC5: PO 11 | AD5: PO 12 | AE5: PO 13 | AF5: PO 14 | AG5: PO 15 | AH5: PO 16 | AI5: PO 17 | AJ5: PO 18 | AK5: PO 19 | AL5: PO 20 | AM5: PO 21 | AN5: PO 22 | AO5: PO 23 | AP5: PO 24 | AQ5: PO 25
A6: Rachel Location | C6: Houston | K6: NC | L6: NC | M6: NC | N6: NC | O6: NC | P6: NC | Q6: NC | R6: NC | S6: NC/Houston | T6: NC/Houston | U6: NC/Houston | V6: NC/Houston | W6: NC/Houston | X6: NC/Houston | Y6: NC/Houston | Z6: NC/Houston | AA6: NC/Houston | AB6: NC/Houston | AC6: NC/Houston | AD6: NC/Houston | AE6: NC/Houston | AF6: NC/Houston | AG6: NC/Houston | AH6: NC/Houston | AI6: NC/Houston | AJ6: NC/Houston | AK6: NC/Houston | AL6: NC/Houston | AM6: NC/Houston | AN6: NC/Houston | AO6: NC/Houston | AP6: NC/Houston
A7: Martin | H7: Business School Start | AE7: New Job Start
A8: Martin Location | C8: Houston | H8: Chicago / Boston / NY | AE8: NY/California/DC | AF8: NY/California/DC | AG8: NY/California/DC | AH8: NY/California/DC | AI8: NY/California/DC | AJ8: NY/California/DC | AK8: NY/California/DC | AL8: NY/California/DC | AM8: NY/California/DC | AN8: NY/California/DC | AO8: NY/California/DC | AP8: NY/California/DC | AQ8: NY/California/DC | AR8: NY/California/DC

Sheet Business School Fund
B7: Costs
B8: Category | C8: Amount (use all positive #s) | D8: Number of Times Billed | E8: Total Cost
B9: Tuition (total sticker amount across 2 years) | C9: 86550 | D9: 2 | E9: =C9*D9 -> 173100
B10: Booth Deposits & Fees Lost | C10: 3400 | D10: 1 | E10: =D10*C10 -> 3400
B11: Student Services Fee | C11: 406 | D11: 2 | E11: =C11*D11 -> 812
B12: Health Insurance | C12: 0 | E12: =C12*D12 -> 0
B13: Computer Allowance | C13: 1000 | D13: 1 | E13: =C13*D13 -> 1000
B14: Clothes | C14: 1000 | D14: 2 | E14: =C14*D14 -> 2000
B15: Clubs / Memberships | C15: 500 | D15: 2 | E15: =C15*D15 -> 1000
B16: Apartment rent/utilities | C16: 1668 | D16: 21 | E16: =C16*D16 -> 35028
B17: Groceries | C17: 400 | D17: 21 | E17: =C17*D17 -> 8400
B18: Transport | C18: 150 | D18: 21 | E18: =C18*D18 -> 3150
B19: Dining out | C19: 300 | D19: 21 | E19: =C19*D19 -> 6300
B20: Travel | C20: 3300 | D20: 6 | E20: =C20*D20 -> 19800
B21: Additional / miscellaneous | C21: 300 | D21: 21 | E21: =C21*D21 -> 6300
B22: Total | E22: =SUM(E8:E21) -> 260290
B29: Financing/Income | G29: Wei Wu Business School Option Fund | L29: Points Expenses | O29: Travel Expenses
B30: Category | C30: Total Available | D30: % Allocation | E30: Actual Allocation | G30: Date | H30: Amount Transferred | L30: 7500 | M30: Amex Points | O30: Amount | P30: Person | Q30: Date | R30: Type
B31: Funding from Mom | C31: 100000 | D31: 1 | E31: =D31*C31 -> 100000 | G31: July 4th | H31: 8500 | O31: 78 | P31: Rachel | Q31: Sept 2024 | R31: Flight
B32: Stocks / Investments - Schwab | C32: 73600 | D32: 0 | E32: =D32*C32 -> 0 | G32: 2024 Rent | H32: =2100*12 -> 25200 | O32: 72 | P32: Rachel | Q32: 45505 | R32: Flight
B33: Treasury MM Fund - VUSXX (Vanguard) | C33: 57000 | D33: 0.5 | E33: =D33*C33 -> 28500 | G33: June 6th | H33: 8500 | O33: 54 | P33: Rachel | Q33: 45566 | R33: Flight
B34: Treasury MM Fund - VUSXX (Chase) | C34: 72000 | D34: 1 | E34: =D34*C34 -> 72000 | G34: May | H34: 8500 | O34: 159 | P34: Martin | Q34: 45566 | R34: Flight | S34: Thanksgiving
B35: Crypto | C35: 16000 | D35: 0 | E35: =D35*C35 -> 0 | G35: April - Birthday | H35: 3000 | I35: Used for Booth Deposit | O35: 112 | P35: Rachel | Q35: 45566 | R35: Flight
B36: Rachel Income ($2k/Mo * 21) | C36: 42000 | D36: 1 | E36: =D36*C36 -> 42000 | G36: April | H36: 7000 | O36: 52 | P36: Rachel | Q36: 45566 | R36: Flight
B37: Internship Salary | C37: 15000 | D37: 1 | E37: =D37*C37 -> 15000 | G37: August | H37: 8000
B38: Total | C38: =SUM(C31:C37) -> 375600 | E38: =SUM(E31:E37) -> 257500 | P38: Rachel Uber
B39: Delta to make up | E39: =E22-E38 -> 2790 | P39: 60 | Q39: Sept 2024
P40: 60 | Q40: Sept 2024
B41: Business School Expenses | C41: Amount | D41: Within Monthly Budget?
B42: Booth Deposit | C42: 3000 | D42: Yes
B43: MIT Deposit | C43: 3500 | D43: No
B44: Random Walk Deposit | C44: 300 | D44: No
B45: Re Vera | C45: 100 | D45: No
B46: Apartment Application Fee | C46: 125 | D46: No
B47: Textbook - Discrete Math | C47: 24.81 | D47: No
B48: Rent (Aug - End of Jan) | C48: 8000 | D48: Yes
B49: Prefunction Trip | C49: 370
B50: Club Dues | C50: 285

Sheet Oct 2023
A4: Monthly Spending | G4: Monthly Overview | J4: Expenses over Time
A5: Category | B5: Budgeted | C5: Amount Spent | D5: Amount Remaining | E5: % Remaining | G5: Income
A6: Fixed | B6: 2663.68 | C6: =sumif($B$20:$C$123,A6,$C$20:$C$123) -> 2693.71 | D6: =B6-C6 -> -30.03 | E6: =D6/B6 -> -0.011273877 | G6: Martin Paycheck | H6: 4950
A7: Utilities | B7: 0 | C7: =sumif($B$20:$C$123,A7,$C$20:$C$123) -> 0 | D7: =B7-C7 -> 0 | E7: =D7/B7 -> #DIV/0! | G7: Rachel Paycheck | H7: ='MartinRachel Pay Stub'!L21 -> 5526
A8: Bills | B8: 250 | C8: =sumif($B$20:$C$123,A8,$C$20:$C$123) -> 0 | D8: =B8-C8 -> 250 | E8: =D8/B8 -> 1
A9: Groceries | B9: 400 | C9: =sumif($B$20:$C$123,A9,$C$20:$C$123) -> 627.85 | D9: =B9-C9 -> -227.85 | E9: =D9/B9 -> -0.569625 | G9: Monthly Expenses
A10: Eating out | B10: 400 | C10: =sumif($B$20:$C$123,A10,$C$20:$C$123) -> 556.37 | D10: =B10-C10 -> -156.37 | E10: =D10/B10 -> -0.390925 | G10: Total Spent | H10: =sum(C16) -> 6435.75
A11: Household Goods | B11: 200 | C11: =sumif($B$20:$C$123,A11,$C$20:$C$123) -> 100 | D11: =B11-C11 -> 100 | E11: =D11/B11 -> 0.5
A12: Travel Fund | B12: 500 | C12: 500 | D12: =B12-C12 -> 0 | E12: =D12/B12 -> 0 | G12: Recurring Expenses
A13: Gas | B13: 200 | C13: =sumif($B$20:$C$123,A13,$C$20:$C$123) -> 298.27 | D13: =B13-C13 -> -98.27 | E13: =D13/B13 -> -0.49135 | G13: Car Insurance
A14: Health | B14: 0 | C14: =sumif($B$20:$C$123,A14,$C$20:$C$123) -> 137 | D14: =B14-C14 -> -137 | E14: =D14/B14 -> #DIV/0!
A15: Fun / Misc | B15: 300 | C15: =sumif($B$20:$C$123,A15,$C$20:$C$123) -> 1522.55 | D15: =B15-C15 -> -1222.55 | E15: =D15/B15 -> -4.0751667 | G15: Amount spent on Travel | H15: =SUMIF($B$20:$C$145,"Travel",$C$20:$C$145) -> 1066.1
A16: Total | B16: =SUM(B6:B15) -> 4913.68 | C16: =SUM(C6:C15) -> 6435.75 | D16: =SUM(D6:D15) -> -1522.07 | E16: =D16/B16 -> -0.30976173 | G16: Amount in Travel Bank | H16: =500-SUMIF($B$20:$C$145,"Travel",$C$20:$C$145)+'Sept 2023'!H16 -> 659.7
A19: Date | B19: Category | C19: Spent | D19: Note
A20: Monthly | B20: Fixed | C20: 2060 | D20: Rent
A21: Monthly | B21: Fixed | C21: 35 | D21: Internet
A22: Monthly | B22: Fixed | C22: 96 | D22: Electric
A23: Monthly | B23: Fixed | C23: 155 | D23: Exercise
A24: Monthly | B24: Fixed | C24: $9,86 | D24: Water
A25: Monthly | B25: Fixed | C25: =1133.34/6 -> 188.89 | D25: Car Insurance
A26: Monthly | B26: Fixed | C26: 2.87 | D26: Spotify - Martin
A27: Monthly | B27: Fixed | C27: 1.99 | D27: Google One
A28: Monthly | B28: Fixed | C28: 5.83 | D28: One Drive
A29: Monthly | B29: Fixed | C29: 148.13 | D29: Phone
A32: 45218 | B32: Travel | C32: 108 | D32: IAH to RDU - RBL
A33: 45200 | B33: Gas | C33: 39.88 | D33: Costco
A34: 45200 | B34: Groceries | C34: 152 | D34: Costco
A35: 45200 | B35: Household Goods | C35: 100 | D35: Costco - air purifier
A36: 45205 | B36: Eating out | C36: 70 | D36: Maht gaek
A37: 45206 | B37: Fun / Misc | C37: 12 | D37: DART - round trip
A38: 45206 | B38: Fun / Misc | C38: =80+52 -> 132 | D38: State fair
A39: 45206 | B39: Eating out | C39: 30 | D39: Gopchangstory
A40: 45206 | B40: Eating out | C40: 32 | D40: Korean fried chicken
A41: 45206 | B41: Gas | C41: 52 | D41: Gas
A42: 45207 | B42: Gas | C42: 40.09 | D42: Costco gas
A43: 45207 | B43: Groceries | C43: 173.88 | D43: Costco
A44: 45206 | B44: Fun / Misc | C44: 3 | D44: Valet
A45: 45207 | B45: Eating out | C45: 14.7 | D45: Taco Bell
A46: 45207 | B46: Eating out | C46: 11.02 | D46: Wendys
A47: 45207 | B47: Groceries | C47: 15 | D47: Heb
...

Sheet Nov 2023
A4: Monthly Spending | G4: Monthly Overview | J4: Expenses over Time
A5: Category | B5: Budgeted | C5: Amount Spent | D5: Amount Remaining | E5: % Remaining | G5: Income
A6: Fixed | B6: 2663.68 | C6: =sumif($B$20:$C$148,A6,$C$20:$C$148) -> 2710.12 | D6: =B6-C6 -> -46.44 | E6: =D6/B6 -> -0.017434527 | G6: Martin Paycheck | H6: =2716+2463+5018 -> 10197
A7: Utilities | B7: 0 | C7: =sumif($B$20:$C$148,A7,$C$20:$C$148) -> 0 | D7: =B7-C7 -> 0 | E7: =D7/B7 -> #DIV/0! | G7: Rachel Paycheck | H7: 5307
A8: Bills | B8: 250 | C8: =sumif($B$20:$C$148,A8,$C$20:$C$148) -> 0 | D8: =B8-C8 -> 250 | E8: =D8/B8 -> 1
A9: Groceries | B9: 400 | C9: =sumif($B$20:$C$148,A9,$C$20:$C$148) -> 265.24 | D9: =B9-C9 -> 134.76 | E9: =D9/B9 -> 0.3369 | G9: Monthly Expenses
A10: Eating out | B10: 400 | C10: =sumif($B$20:$C$148,A10,$C$20:$C$148) -> 2642.64 | D10: =B10-C10 -> -2242.64 | E10: =D10/B10 -> -5.6066 | G10: Total Spent | H10: =sum(C16) -> 10830.42
A11: Household Goods | B11: 200 | C11: =sumif($B$20:$C$148,A11,$C$20:$C$148) -> 902.51 | D11: =B11-C11 -> -702.51 | E11: =D11/B11 -> -3.51255
A12: Travel | B12: 500 | C12: 500 | D12: =B12-C12 -> 0 | E12: =D12/B12 -> 0 | G12: Recurring Expenses
A13: Gas | B13: 200 | C13: =sumif($B$20:$C$148,A13,$C$20:$C$148) -> 79.78 | D13: =B13-C13 -> 120.22 | E13: =D13/B13 -> 0.6011 | G13: Car Insurance
A14: Health | B14: 0 | C14: =sumif($B$20:$C$148,A14,$C$20:$C$148) -> 61 | D14: =B14-C14 -> -61 | E14: =D14/B14 -> #DIV/0!
A15: Fun / Misc | B15: 300 | C15: =sumif($B$20:$C$148,A15,$C$20:$C$148) -> 3669.13 | D15: =B15-C15 -> -3369.13 | E15: =D15/B15 -> -11.230433 | G15: Amount spent on Travel | H15: =SUMIF($B$20:$C$170,"Travel",$C$20:$C$170) -> 1774.04
A16: Total | B16: =SUM(B6:B15) -> 4913.68 | C16: =SUM(C6:C15) -> 10830.42 | D16: =SUM(D6:D15) -> -5916.74 | E16: =D16/B16 -> -1.2041362 | G16: Amount in Travel Bank | H16: =500-SUMIF($B$20:$C$170,"Travel",$C$20:$C$170)+'Oct 2023'!H16 -> -614.34
A19: Date | B19: Category | C19: Spent | D19: Note
A20: Monthly | B20: Fixed | C20: 2060 | D20: Rent
A21: Monthly | B21: Fixed | C21: 55 | D21: Internet
A22: Monthly | B22: Fixed | C22: 81.55 | D22: Electric
A23: Monthly | B23: Fixed | C23: 156 | D23: Exercise
A24: Monthly | B24: Fixed | C24: 9.86 | D24: Water
A25: Monthly | B25: Fixed | C25: =1133.34/6 -> 188.89 | D25: Car Insurance
A26: Monthly | B26: Fixed | C26: 2.87 | D26: Spotify - Martin
A27: Monthly | B27: Fixed | C27: 1.99 | D27: Google One
A28: Monthly | B28: Fixed | C28: 5.83 | D28: One Drive
A29: Monthly | B29: Fixed | C29: 148.13 | D29: Phone
A32: 45232 | B32: Travel | C32: =8.9*2+53.78+123.78+191.61 -> 386.97 | D32: Vegas FLight & Hotel
A33: 45241 | B33: Fun / Misc | C33: 89 | D33: Verizon Stuff
A34: 45247 | B34: Travel | C34: =542.5*2 -> 1085 | D34: Maldives
A35: 45236 | B35: Eating out | C35: 20.42 | D35: Lunch in Vegas
A36: 45239 | B36: Eating Out | C36: 9.73 | D36: Rachel Lunch
A37: 45247 | B37: Gas | C37: 11.68 | D37: Rachel Gas
A38: 45233 | B38: Eating Out | C38: 23.38 | D38: Panda Express
A39: 45235 | B39: Fun / Misc | C39: 1.5 | D39: parking
A40: 45235 | B40: Eating out | C40: 32 | D40: Travel Insurance
A41: 45250 | B41: Groceries | C41: 10.87 | D41: Great Wall Groceries
A42: 45251 | B42: Eating out | C42: 60.44 | D42: Mein
A43: 45252 | B43: Fun / Misc | C43: 54.54 | D43: Louve Tix
A44: 45253 | B44: Fun / Misc | C44: 160 | D44: GRE
A45: 45254 | B45: Groceries | C45: 34.98 | D45: HMart Groceries
A46: 45255 | B46: Eating out | C46: 45.08 | D46: Local Foods
... A54: 45237 | B54: Eating out | C54: 15.17 | D54: Cosmo Lunch
...

Sheet Dec 2023
A4: Monthly Spending | G4: Monthly Overview | J4: Expenses over Time
A5: Category | B5: Budgeted | C5: Amount Spent | D5: Amount Remaining | E5: % Remaining | G5: Income
A6: Fixed | B6: 2663.68 | C6: =sumif($B$20:$C$127,A6,$C$20:$C$127) -> 2710.12 | D6: =B6-C6 -> -46.44 | E6: =D6/B6 -> -0.017434527 | G6: Martin Paycheck | H6: ='MartinRachel Pay Stub'!B20*2 -> 3851.86
A7: Utilities | B7: 0 | C7: =sumif($B$20:$C$127,A7,$C$20:$C$127) -> 0 | D7: =B7-C7 -> 0 | E7: =D7/B7 -> #DIV/0! | G7: Rachel Paycheck | H7: ='MartinRachel Pay Stub'!E20*2 -> 5429.1
A8: Bills | B8: 250 | C8: =sumif($B$20:$C$127,A8,$C$20:$C$127) -> 0 | D8: =B8-C8 -> 250 | E8: =D8/B8 -> 1
A9: Groceries | B9: 400 | C9: =sumif($B$20:$C$127,A9,$C$20:$C$127) -> 802.61 | D9: =B9-C9 -> -402.61 | E9: =D9/B9 -> -1.006525 | G9: Monthly Expenses
A10: Eating out | B10: 400 | C10: =sumif($B$20:$C$127,A10,$C$20:$C$127) -> 843.17 | D10: =B10-C10 -> -443.17 | E10: =D10/B10 -> -1.107925 | G10: Total Spent | H10: =sum(C16) -> 7536.32
A11: Household Goods | B11: 200 | C11: =sumif($B$20:$C$127,A11,$C$20:$C$127) -> 488.22 | D11: =B11-C11 -> -288.22 | E11: =D11/B11 -> -1.4411
A12: Travel | B12: 500 | C12: 500 | D12: =B12-C12 -> 0 | E12: =D12/B12 -> 0 | G12: Recurring Expenses
A13: Gas | B13: 200 | C13: =sumif($B$20:$C$127,A13,$C$20:$C$127) -> 42.68 | D13: =B13-C13 -> 157.32 | E13: =D13/B13 -> 0.7866 | G13: Car Insurance
A14: Health | B14: 0 | C14: =sumif($B$20:$C$127,A14,$C$20:$C$127) -> 14.45 | D14: =B14-C14 -> -14.45 | E14: =D14/B14 -> #DIV/0!
A15: Fun / Misc | B15: 300 | C15: =sumif($B$20:$C$127,A15,$C$20:$C$127) -> 2135.07 | D15: =B15-C15 -> -1835.07 | E15: =D15/B15 -> -6.1169 | G15: Amount spent on Travel | H15: =SUMIF($B$20:$C$149,"Travel",$C$20:$C$149) -> 21
A16: Total | B16: =SUM(B6:B15) -> 4913.68 | C16: =SUM(C6:C15) -> 7536.32 | D16: =SUM(D6:D15) -> -2622.64 | E16: =D16/B16 -> -0.53374253 | G16: Amount in Travel Bank | H16: =500-SUMIF($B$20:$C$149,"Travel",$C$20:$C$149)+'Nov 2023'!H16 -> -135.34
A19: Date | B19: Category | C19: Spent | D19: Note
A20: Monthly | B20: Fixed | C20: 2060 | D20: Rent
A21: Monthly | B21: Fixed | C21: 55 | D21: Internet
A22: Monthly | B22: Fixed | C22: 81.55 | D22: Electric
A23: Monthly | B23: Fixed | C23: 156 | D23: Exercise
A24: Monthly | B24: Fixed | C24: 9.86 | D24: Water
A25: Monthly | B25: Fixed | C25: =1133.34/6 -> 188.89 | D25: Car Insurance
A26: Monthly | B26: Fixed | C26: 2.87 | D26: Spotify - Martin
A27: Monthly | B27: Fixed | C27: 1.99 | D27: Google One
A28: Monthly | B28: Fixed | C28: 5.83 | D28: One Drive
A29: Monthly | B29: Fixed | C29: 148.13 | D29: Phone
A32: 45270 | B32: Groceries | C32: 145.69 | D32: Costco
A33: 45262 | B33: Groceries | C33: 183.25 | D33: Costco
A34: 45268 | B34: Fun / Misc | C34: 8.55 | D34: PIrate Ship
A35: 45262 | B35: Groceries | C35: 30.55 | D35: Hmart
A36: 45270 | B36: Fun / Misc | C36: 113.68 | D36: Go-karting
A37: 45269 | B37: Fun / Misc | C37: 19.37 | D37: Book
A38: 45268 | B38: Eating out | C38: 24.01 | D38: Raising Canes
A39: 45269 | B39: Eating out | C39: 40.86 | D39: Dimsum
A40: 45270 | B40: Eating out | C40: 18 | D40: Tacos
A41: 45270 | B41: Fun / Misc | C41: 1923.7 | D41: Family Trip
A42: 45270 | B42: Fun / Misc | D42: Boat Rental
A43: 45262 | B43: Eating out | C43: =25.95*2/3 -> 17.3 | D43: Roostar
A44: 45268 | B44: Household Goods | C44: 207 | D44: Adidas
A45: 45266 | B45: Health | C45: 14.45 | D45: Mucinex
A46: 45262 | B46: Eating out | C46: =65-18 -> 47 | D46: Wings + pizza
A47: 45262 | B47: Household Goods | C47: -25 | D47: leather jackets
...

Sheet Jan 2024
A4: Monthly Spending | G4: Monthly Overview | J4: Expenses over Time
A5: Category | B5: Budgeted | C5: Amount Spent | D5: Amount Remaining | E5: % Remaining | G5: Income
A6: Fixed | B6: 2663.68 | C6: =sumif($B$20:$C$100,A6,$C$20:$C$100) -> 2660.12 | D6: =B6-C6 -> 3.56 | E6: =D6/B6 -> 0.0013364969 | G6: Martin Paycheck | H6: =1473*2 -> 2946
A7: Utilities | B7: 0 | C7: =sumif($B$20:$C$100,A7,$C$20:$C$100) -> 0 | D7: =B7-C7 -> 0 | E7: =D7/B7 -> #DIV/0! | G7: Rachel Paycheck | H7: ='MartinRachel Pay Stub'!E20*2 -> 5429.1
A8: Bills | B8: 250 | C8: =sumif($B$20:$C$100,A8,$C$20:$C$100) -> 1991.45 | D8: =B8-C8 -> -1741.45 | E8: =D8/B8 -> -6.9658
A9: Groceries | B9: 400 | C9: =sumif($B$20:$C$100,A9,$C$20:$C$100) -> 650.42 | D9: =B9-C9 -> -250.42 | E9: =D9/B9 -> -0.62605 | G9: Monthly Expenses
A10: Eating out | B10: 400 | C10: =sumif($B$20:$C$100,A10,$C$20:$C$100) -> 390.16 | D10: =B10-C10 -> 9.84 | E10: =D10/B10 -> 0.0246 | G10: Total Spent | H10: =sum(C16) -> 7230.99
A11: Household Goods | B11: 200 | C11: =sumif($B$20:$C$100,A11,$C$20:$C$100) -> 597.65 | D11: =B11-C11 -> -397.65 | E11: =D11/B11 -> -1.98825
A12: Travel | B12: 500 | C12: 500 | D12: =B12-C12 -> 0 | E12: =D12/B12 -> 0 | G12: Recurring Expenses
A13: Gas | B13: 200 | C13: =sumif($B$20:$C$100,A13,$C$20:$C$100) -> 64.19 | D13: =B13-C13 -> 135.81 | E13: =D13/B13 -> 0.67905 | G13: Car Insurance
A14: Health | B14: 0 | C14: =sumif($B$20:$C$100,A14,$C$20:$C$100) -> 112 | D14: =B14-C14 -> -112 | E14: =D14/B14 -> #DIV/0!
A15: Fun / Misc | B15: 300 | C15: =sumif($B$20:$C$100,A15,$C$20:$C$100) -> 265 | D15: =B15-C15 -> 35 | E15: =D15/B15 -> 0.11666667 | G15: Amount spent on Travel | H15: =SUMIF($B$20:$C$122,"Travel",$C$20:$C$122) -> 440
A16: Total | B16: =SUM(B6:B15) -> 4913.68 | C16: =SUM(C6:C15) -> 7230.99 | D16: =SUM(D6:D15) -> -2317.31 | E16: =D16/B16 -> -0.47160377 | G16: Amount in Travel Bank | H16: =500-SUMIF($B$20:$C$122,"Travel",$C$20:$C$122)+'Dec 2023'!H16 -> -75.34
A19: Date | B19: Category | C19: Spent | D19: Note
A20: Monthly | B20: Fixed | C20: 2060 | D20: Rent
A21: Monthly | B21: Fixed | C21: 5 | D21: Internet
A22: Monthly | B22: Fixed | C22: 81.55 | D22: Electric
A23: Monthly | B23: Fixed | C23: 156 | D23: Exercise
A24: Monthly | B24: Fixed | C24: 9.86 | D24: Water
A25: Monthly | B25: Fixed | C25: =1133.34/6 -> 188.89 | D25: Car Insurance
A26: Monthly | B26: Fixed | C26: 2.87 | D26: Spotify - Martin
A27: Monthly | B27: Fixed | C27: 1.99 | D27: Google One
A28: Monthly | B28: Fixed | C28: 5.83 | D28: One Drive
A29: Monthly | B29: Fixed | C29: 148.13 | D29: Phone
A32: 45304 | B32: Household Goods | C32: 295 | D32: Jcrew
A33: 45304 | B33: Household Goods | C33: 0 | D33: Jcrew - Caml Hair
A34: 45293 | B34: Eating out | C34: 9.73 | D34: Citiline
A35: 45298 | B35: Groceries | C35: 14.5 | D35: WF
A36: 45298 | B36: Groceries | C36: 31.51 | D36: HEB
A37: 45300 | B37: Bills | C37: 5.95 | D37: Parking
A38: 45297 | B38: Eating out | C38: 17.3 | D38: Domion's
A39: 45295 | B39: Gas | C39: 22.3 | D39: Rachel Gas
A40: 45295 | B40: Groceries | C40: 171.37 | D40: Costco
A41: 45295 | B41: Eating out | C41: 7.37 | D41: Costco
A42: 45294 | B42: Fun / Misc | C42: 5 | D42: Parking Drop off
A43: 45294 | B43: Fun / Misc | C43: 55 | D43: Rockets Tickets
... A74: 45318 | B74: Groceries | C74: 4 | D74: whole foods
A75: 45319 | B75: Fun / Misc

Sheet Feb 2024
A4: Monthly Spending | G4: Monthly Overview | J4: Expenses over Time
A5: Category | B5: Budgeted | C5: Amount Spent | D5: Amount Remaining | E5: % Remaining | G5: Income
A6: Fixed | B6: 2663.68 | C6: =sumif($B$20:$C$103,A6,$C$20:$C$103) -> 2732.67 | D6: =B6-C6 -> -68.99 | E6: =D6/B6 -> -0.025900258 | G6: Martin Paycheck | H6: =1881+2005 -> 3886
A7: Utilities | B7: 0 | C7: =sumif($B$20:$C$103,A7,$C$20:$C$103) -> 0 | D7: =B7-C7 -> 0 | E7: =D7/B7 -> #DIV/0! | G7: Rachel Paycheck | H7: 4400
A8: Bills | B8: 250 | C8: =sumif($B$20:$C$103,A8,$C$20:$C$103) -> 658.62 | D8: =B8-C8 -> -408.62 | E8: =D8/B8 -> -1.63448 | G8: Total | H8: =SUM(H6:H7) -> 8286
A9: Groceries | B9: 400 | C9: =sumif($B$20:$C$103,A9,$C$20:$C$103) -> 344.74 | D9: =B9-C9 -> 55.26 | E9: =D9/B9 -> 0.13815
A10: Eating out | B10: 400 | C10: =sumif($B$20:$C$103,A10,$C$20:$C$103) -> 456.54 | D10: =B10-C10 -> -56.54 | E10: =D10/B10 -> -0.14135 | G10: Monthly Expenses
A11: Household Goods | B11: 200 | C11: =sumif($B$20:$C$103,A11,$C$20:$C$103) -> 16.35 | D11: =B11-C11 -> 183.65 | E11: =D11/B11 -> 0.91825 | G11: Total Spent | H11: =sum(C16) -> 6377.04
A12: Travel | B12: 500 | C12: 500 | D12: =B12-C12 -> 0 | E12: =D12/B12 -> 0
A13: Gas | B13: 200 | C13: =sumif($B$20:$C$103,A13,$C$20:$C$103) -> 101.47 | D13: =B13-C13 -> 98.53 | E13: =D13/B13 -> 0.49265 | G13: Recurring Expenses
A14: Health | B14: 0 | C14: =sumif($B$20:$C$103,A14,$C$20:$C$103) -> 480 | D14: =B14-C14 -> -480 | E14: =D14/B14 -> #DIV/0! | G14: Car Insurance
A15: Fun / Misc | B15: 300 | C15: =sumif($B$20:$C$103,A15,$C$20:$C$103) -> 1086.65 | D15: =B15-C15 -> -786.65 | E15: =D15/B15 -> -2.6221667
A16: Total | B16: =SUM(B6:B15) -> 4913.68 | C16: =SUM(C6:C15) -> 6377.04 | D16: =SUM(D6:D15) -> -1463.36 | E16: =D16/B16 -> -0.29781345 | G16: Amount spent on Travel | H16: =SUMIF($B$20:$C$125,"Travel",$C$20:$C$125) -> 274.2
G17: Amount in Travel Bank | H17: =500-SUMIF($B$20:$C$125,"Travel",$C$20:$C$125)+'Jan 2024'!H16 -> 150.46
A19: Date | B19: Category | C19: Spent | D19: Note
A20: Monthly | B20: Fixed | C20: 2060 | D20: Rent
A21: Monthly | B21: Fixed | C21: 55 | D21: Internet
A22: Monthly | B22: Fixed | C22: 97.85 | D22: Electric
A23: Monthly | B23: Fixed | C23: 156 | D23: Exercise
A24: Monthly | B24: Fixed | C24: 9.86 | D24: Water
A25: Monthly | B25: Fixed | C25: =1133.34/6 -> 188.89 | D25: Car Insurance
A26: Monthly | B26: Fixed | C26: 2.87 | D26: Spotify - Martin
A27: Monthly | B27: Fixed | C27: 1.99 | D27: Google One
A28: Monthly | B28: Fixed | C28: 5.83 | D28: One Drive
A29: Monthly | B29: Fixed | C29: 6.25 | D29: MSFT
A30: Monthly | B30: Fixed | C30: 148.13 | D30: Phone
A33: 45337 | B33: Bills | C33: 48 | D33: Airport Parking
A34: 45327 | B34: Eating out | C34: 22 | D34: Chipotle
A35: 45337 | B35: Bills | C35: 551 | D35: Flight to RDU - Duke Interview
B36: Eating out | C36: 24.9 | D36: LUNA PIZZERIA - KIRBY
B37: Travel | C37: 40 | D37: AAA H GALLERIA-R
B38: Eating out | C38: 3.25 | D38: Dinner Parking
B39: Groceries | C39: 123 | D39: COSTCO WHSE #1018
B40: Groceries | C40: 20.52 | D40: H-E-B #630
B41: Eating out | C41: 24.32 | D41: TST* BURGER JOINT MONTROS
B42: Gas | C42: 39.37 | D42: Gas - Martin
B43: Fun / Misc | C43: 184.01 | D43: Valentines Gift
B44: Travel | C44: 36.78 | D44: Passport Photos
B45: Travel | C45: 143 | D45: Costco
B46: Fun / Misc | C46: =93.65*2/3 -> 62.433333 | D46: Italy Tickets
...

Sheet March 2024
A4: Monthly Spending | G4: Monthly Overview | J4: Expenses over Time
A5: Category | B5: Budgeted | C5: Amount Spent | D5: Amount Remaining | E5: % Remaining | G5: Income
A6: Fixed | B6: 2663.68 | C6: =sumif($B$20:$C$102,A6,$C$20:$C$102) -> 4184.1967 | D6: =B6-C6 -> -1520.5167 | E6: =D6/B6 -> -0.57083308 | G6: Martin Paycheck | H6: =2002*2 -> 4004
A7: Utilities | B7: 0 | C7: =sumif($B$20:$C$102,A7,$C$20:$C$102) -> 0 | D7: =B7-C7 -> 0 | E7: =D7/B7 -> #DIV/0! | G7: Rachel Paycheck | H7: =2024+805+2035 -> 4864
A8: Bills | B8: 250 | C8: =sumif($B$20:$C$102,A8,$C$20:$C$102) -> 66 | D8: =B8-C8 -> 184 | E8: =D8/B8 -> 0.736 | G8: Total | H8: =SUM(H6:H7) -> 8868
A9: Groceries | B9: 400 | C9: =sumif($B$20:$C$102,A9,$C$20:$C$102) -> 244.79 | D9: =B9-C9 -> 155.21 | E9: =D9/B9 -> 0.388025
A10: Eating out | B10: 400 | C10: =sumif($B$20:$C$102,A10,$C$20:$C$102) -> 520.56 | D10: =B10-C10 -> -120.56 | E10: =D10/B10 -> -0.3014 | G10: Monthly Expenses
A11: Household Goods | B11: 200 | C11: =sumif($B$20:$C$102,A11,$C$20:$C$102) -> 1369.11 | D11: =B11-C11 -> -1169.11 | E11: =D11/B11 -> -5.84555 | G11: Total Spent | H11: =sum(C16) -> 9041.8767
A12: Travel | B12: 500 | C12: 500 | D12: =B12-C12 -> 0 | E12: =D12/B12 -> 0
A13: Gas | B13: 200 | C13: =sumif($B$20:$C$102,A13,$C$20:$C$102) -> 390.02 | D13: =B13-C13 -> -190.02 | E13: =D13/B13 -> -0.9501 | G13: Recurring Expenses
A14: Health | B14: 0 | C14: =sumif($B$20:$C$102,A14,$C$20:$C$102) -> 0 | D14: =B14-C14 -> 0 | E14: =D14/B14 -> #DIV/0! | G14: Car Insurance
A15: Fun / Misc | B15: 300 | C15: =sumif($B$20:$C$102,A15,$C$20:$C$102) -> 1767.2 | D15: =B15-C15 -> -1467.2 | E15: =D15/B15 -> -4.8906667
A16: Total | B16: =SUM(B6:B15) -> 4913.68 | C16: =SUM(C6:C15) -> 9041.8767 | D16: =SUM(D6:D15) -> -4128.1967 | E16: =D16/B16 -> -0.84014357 | G16: Amount spent on Travel | H16: =SUMIF($B$20:$C$124,"Travel",$C$20:$C$124) -> 469.18
G17: Amount in Travel Bank | H17: =500-SUMIF($B$20:$C$124,"Travel",$C$20:$C$124)+'Feb 2024'!H17 -> 181.28
A19: Date | B19: Category | C19: Spent | D19: Note
A20: Monthly | B20: Fixed | C20: =3720 -> 3720 | D20: Rent
A21: Monthly | B21: Fixed | C21: 40 | D21: Internet
A22: Monthly | B22: Fixed | C22: 97.85 | D22: Electric
A23: Monthly | B23: Fixed | D23: Exercise
A24: Monthly | B24: Fixed | C24: 9.86 | D24: Water
A25: Monthly | B25: Fixed | C25: =77/12 -> 6.4166667 | D25: Renters insurance
A26: Monthly | B26: Fixed | C26: 144 | D26: Car Insurance
A27: Monthly | B27: Fixed | C27: 2.87 | D27: Spotify - Martin
A28: Monthly | B28: Fixed | C28: 2.99 | D28: Google One
A29: Monthly | B29: Fixed | C29: 5.83 | D29: One Drive
A30: Monthly | B30: Fixed | C30: 6.25 | D30: MSFT
A31: Monthly | B31: Fixed | C31: 148.13 | D31: Phone
A34: 45363 | B34: Groceries | C34: 18.78 | D34: whole foods
A35: 45368 | B35: Household Goods | C35: 19.61 | D35: amazon
A36: 45367 | B36: Household Goods | C36: 35.51 | D36: amazon
A37: 45370 | B37: Groceries | C37: 55.01 | D37: gin and tonic
A38: 45360 | B38: Fun / Misc | C38: 172.66 | D38: glass gifts
A39: 45362 | B39: Fun / Misc | C39: 5.75 | D39: office parking
B40: Travel | C40: 247.78 | D40: italy train tickets
B41: Eating out | C41: 28.01 | D41: burger joint
B42: Eating out | C42: 67.07 | D42: cooking girl
B43: Eating out | C43: 35.75 | D43: travel meals
B44: Fun / Misc | C44: 27.79 | D44: sim cards
B45: Fun / Misc | C45: 800 | D45: italy pt 1
B46: Fun / Misc | C46: 380 | D46: italy p2
...

Sheet April 2024
A4: Monthly Spending | G4: Monthly Overview | J4: Expenses over Time
A5: Category | B5: Budgeted | C5: Amount Spent | D5: Amount Remaining | E5: % Remaining | G5: Income
A6: Fixed | B6: 2663.68 | C6: =sumif($B$20:$C$102,A6,$C$20:$C$102) -> 3387.9767 | D6: =B6-C6 -> -724.29667 | E6: =D6/B6 -> -0.2719158 | G6: Martin Paycheck | H6: 5000
A7: Utilities | B7: 0 | C7: =sumif($B$20:$C$102,A7,$C$20:$C$102) -> 0 | D7: =B7-C7 -> 0 | E7: =D7/B7 -> #DIV/0! | G7: Rachel Paycheck | H7: 4200
A8: Bills | B8: 250 | C8: =sumif($B$20:$C$102,A8,$C$20:$C$102) -> 2110.47 | D8: =B8-C8 -> -1860.47 | E8: =D8/B8 -> -7.44188 | G8: Total | H8: =SUM(H6:H7) -> 9200
A9: Groceries | B9: 400 | C9: =sumif($B$20:$C$102,A9,$C$20:$C$102) -> 1097.74 | D9: =B9-C9 -> -697.74 | E9: =D9/B9 -> -1.74435
A10: Eating out | B10: 400 | C10: =sumif($B$20:$C$102,A10,$C$20:$C$102) -> 431.61 | D10: =B10-C10 -> -31.61 | E10: =D10/B10 -> -0.079025 | G10: Monthly Expenses
A11: Household Goods | B11: 200 | C11: =sumif($B$20:$C$102,A11,$C$20:$C$102) -> 511.78 | D11: =B11-C11 -> -311.78 | E11: =D11/B11 -> -1.5589 | G11: Total Spent | H11: =sum(C17) -> 13059.367
A12: Travel | B12: 500 | C12: 500 | D12: =B12-C12 -> 0 | E12: =D12/B12 -> 0
A13: Gas | B13: 200 | C13: =sumif($B$20:$C$102,A13,$C$20:$C$102) -> 44.74 | D13: =B13-C13 -> 155.26 | E13: =D13/B13 -> 0.7763 | G13: Recurring Expenses
A14: Health | B14: 0 | C14: =sumif($B$20:$C$102,A14,$C$20:$C$102) -> 380.69 | D14: =B14-C14 -> -380.69 | E14: =D14/B14 -> #DIV/0! | G14: Car Insurance
A15: Fun / Misc | B15: 300 | C15: =sumif($B$20:$C$102,A15,$C$20:$C$102) -> 215.36 | D15: =B15-C15 -> 84.64 | E15: =D15/B15 -> 0.28213333
A16: Business School | B16: 0 | C16: =sumif($B$20:$C$102,A16,$C$20:$C$102) -> 4379 | D16: =B16-C16 -> -4379 | E16: =D16/B16 -> #DIV/0! | G16: Amount spent on Travel | H16: =SUMIF($B$20:$C$124,"Travel",$C$20:$C$124) -> 178.04
A17: Total | B17: =SUM(B6:B16) -> 4913.68 | C17: =SUM(C6:C16) -> 13059.367 | D17: =SUM(D6:D15) -> -3766.6867 | E17: =D17/B17 -> -0.76657142 | G17: Amount in Travel Bank | H17: =500-SUMIF($B$20:$C$124,"Travel",$C$20:$C$124)+'March 2024'!H17 -> 503.24
A19: Date | B19: Category | C19: Spent | D19: Note
A20: Monthly | B20: Fixed | C20: 2900 | D20: Rent
A21: Monthly | B21: Fixed | C21: 40 | D21: Internet
A22: Monthly | B22: Fixed | C22: 40 | D22: Electric
A23: Monthly | B23: Fixed | C23: 42.62 | D23: Exercise
A24: Monthly | B24: Fixed | C24: 87 | D24: Gas
A25: Monthly | B25: Fixed | C25: =77/12 -> 6.4166667 | D25: Renters insurance
A26: Monthly | B26: Fixed | C26: 144 | D26: Car Insurance
A27: Monthly | B27: Fixed | C27: 2.87 | D27: Spotify - Martin
A28: Monthly | B28: Fixed | C28: 2.99 | D28: Google One
A29: Monthly | B29: Fixed | C29: 5.83 | D29: One Drive
A30: Monthly | B30: Fixed | C30: 6.25 | D30: MSFT
A31: Monthly | B31: Fixed | C31: 110 | D31: Phone
A34: 45384 | B34: Health | C34: 40.69 | D34: Theraband
B35: Fun / Misc | C35: 75 | D35: Josh Present
B36: Eating out | C36: 33.25 | D36: Bakery
B37: Groceries | C37: 161.45 | D37: Asia Grocery Store
B38: Household Goods | C38: 121.28 | D38: Dry Cleaning
B39: Bills | C39: 7.64 | D39: Rhythm
B40: Groceries | C40: 143.93 | D40: Costco
B41: Groceries | C41: 180.58 | D41: Costco
B42: Groceries | C42: -12.8 | D42: Costco Refund
B43: Groceries | C43: 6.92 | D43: Costco
B44: Groceries | C44: -160 | D44: Costco
B45: Eating out | C45: 276 | D45: Lingo
B46: Fun / Misc | C46: 8.61 | D46: NY Uber
...

Sheet May 2024
A4: Monthly Spending | G4: Monthly Overview | J4: Expenses over Time
A5: Category | B5: Budgeted | C5: Amount Spent | D5: Amount Remaining | E5: % Remaining | G5: Income
A6: Fixed | B6: 2663.68 | C6: =sumif($B$20:$C$101,A6,$C$20:$C$101) -> 3397.9767 | D6: =B6-C6 -> -734.29667 | E6: =D6/B6 -> -0.27567 | G6: Martin Paycheck | H6: =3223+2061 -> 5284
A7: Utilities | B7: 0 | C7: =sumif($B$20:$C$101,A7,$C$20:$C$101) -> 0 | D7: =B7-C7 -> 0 | E7: =D7/B7 -> #DIV/0! | G7: Rachel Paycheck | H7: =3370*2 -> 6740
A8: Bills | B8: 250 | C8: =sumif($B$20:$C$101,A8,$C$20:$C$101) -> 404.6 | D8: =B8-C8 -> -154.6 | E8: =D8/B8 -> -0.6184 | G8: Total | H8: =SUM(H6:H7) -> 12024
A9: Groceries | B9: 400 | C9: =sumif($B$20:$C$101,A9,$C$20:$C$101) -> 407.21 | D9: =B9-C9 -> -7.21 | E9: =D9/B9 -> -0.018025
A10: Eating out | B10: 400 | C10: =sumif($B$20:$C$101,A10,$C$20:$C$101) -> 392.61 | D10: =B10-C10 -> 7.39 | E10: =D10/B10 -> 0.018475 | G10: Monthly Expenses
A11: Household Goods | B11: 200 | C11: =sumif($B$20:$C$101,A11,$C$20:$C$101) -> 68.85 | D11: =B11-C11 -> 131.15 | E11: =D11/B11 -> 0.65575 | G11: Total Spent | H11: =sum(C17) -> 6570.3467
A12: Travel | B12: 500 | C12: 500 | D12: =B12-C12 -> 0 | E12: =D12/B12 -> 0
A13: Gas | B13: 200 | C13: =sumif($B$20:$C$101,A13,$C$20:$C$101) -> 110.11 | D13: =B13-C13 -> 89.89 | E13: =D13/B13 -> 0.44945 | G13: Recurring Expenses
A14: Health | B14: 0 | C14: =sumif($B$20:$C$101,A14,$C$20:$C$101) -> 15.64 | D14: =B14-C14 -> -15.64 | E14: =D14/B14 -> #DIV/0! | G14: Car Insurance
A15: Fun / Misc | B15: 300 | C15: =sumif($B$20:$C$101,A15,$C$20:$C$101) -> 1066.14 | D15: =B15-C15 -> -766.14 | E15: =D15/B15 -> -2.5538
A16: Business School | B16: 0 | C16: =sumif($B$20:$C$101,A16,$C$20:$C$101) -> 207.21 | D16: =B16-C16 -> -207.21 | E16: =D16/B16 -> #DIV/0! | G16: Amount spent on Travel | H16: =SUMIF($B$20:$C$123,"Travel",$C$20:$C$123) -> 643.79
A17: Total | B17: =SUM(B6:B16) -> 4913.68 | C17: =SUM(C6:C16) -> 6570.3467 | D17: =SUM(D6:D15) -> -1449.4567 | E17: =D17/B17 -> -0.29498394 | G17: Amount in Travel Bank | H17: =500-SUMIF($B$20:$C$123,"Travel",$C$20:$C$123)+'April 2024'!H17 -> 359.45
A19: Date | B19: Category | C19: Spent | D19: Note
A20: Monthly | B20: Fixed | C20: 2900 | D20: Rent
A21: Monthly | B21: Fixed | C21: 40 | D21: Internet
A22: Monthly | B22: Fixed | C22: 50 | D22: Electric
A23: Monthly | B23: Fixed | C23: 42.62 | D23: Exercise
A24: Monthly | B24: Fixed | C24: 87 | D24: Gas
A25: Monthly | B25: Fixed | C25: =77/12 -> 6.4166667 | D25: Renters insurance
A26: Monthly | B26: Fixed | C26: 144 | D26: Car Insurance
A27: Monthly | B27: Fixed | C27: 2.87 | D27: Spotify - Martin
A28: Monthly | B28: Fixed | C28: 2.99 | D28: Google One
A29: Monthly | B29: Fixed | C29: 5.83 | D29: One Drive
A30: Monthly | B30: Fixed | C30: 6.25 | D30: MSFT
A31: Monthly | B31: Fixed | C31: 110 | D31: Phone
A34: 45433 | B34: Eating out | C34: 8.68 | D34: BASF Lunch
A35: 45416 | B35: Fun / Misc | C35: =4*2.9+2.9*2 -> 17.4 | D35: MTA
A36: 45416 | B36: Fun / Misc | C36: 12.24 | D36: Walmart
A37: 45416 | B37: Fun / Misc | C37: 7.7 | D37: Morristown Parking
A38: 45416 | B38: Eating out | C38: 101 | D38: Samwoojang Korean Lunch
A39: 45417 | B39: Eating out | C39: 21.26 | D39: Tiki Chick
A40: 45417 | B40: Groceries | C40: 56.12 | D40: Kan Mam
A41: 45417 | B41: Groceries | C41: 96.74 | D41: Costco
A43: 45420 | B43: Travel | C43: 24 | D43: Airalo-Esim
A44: 45421 | B44: Eating out | C44: 13.41 | D44: Deez nuts
A45: 45421 | B45: Eating out | C45: 4 | D45: EWR Water
A46: 45421 | B46: Fun / Misc | C46: 324 | D46: Costa Rica ATM Pull
A47: 45421 | B47: Groceries | C47: 3.48 | D47: Costco
...

Sheet June 2024
A4: Monthly Spending | G4: Monthly Overview | J4: Expenses over Time
A5: Category | B5: Budgeted | C5: Amount Spent | D5: Amount Remaining | E5: % Remaining | G5: Income
A6: Fixed | B6: 2663.68 | C6: =sumif($B$20:$C$101,A6,$C$20:$C$101) -> 3432.9767 | D6: =B6-C6 -> -769.29667 | E6: =D6/B6 -> -0.28880972 | G6: Martin Paycheck | H6: =3061+3061 -> 6122
A7: Utilities | B7: 0 | C7: =sumif($B$20:$C$101,A7,$C$20:$C$101) -> 0 | D7: =B7-C7 -> 0 | E7: =D7/B7 -> #DIV/0! | G7: Rachel Paycheck | H7: =3410+3395 -> 6805
A8: Bills | B8: 250 | C8: =sumif($B$20:$C$101,A8,$C$20:$C$101) -> 0 | D8: =B8-C8 -> 250 | E8: =D8/B8 -> 1 | G8: Total | H8: =SUM(H6:H7) -> 12927
A9: Groceries | B9: 400 | C9: =sumif($B$20:$C$101,A9,$C$20:$C$101) -> 658.35 | D9: =B9-C9 -> -258.35 | E9: =D9/B9 -> -0.645875
A10: Eating out | B10: 400 | C10: =sumif($B$20:$C$101,A10,$C$20:$C$101) -> 746.7 | D10: =B10-C10 -> -346.7 | E10: =D10/B10 -> -0.86675 | G10: Monthly Expenses
A11: Household Goods | B11: 200 | C11: =sumif($B$20:$C$101,A11,$C$20:$C$101) -> 213.67 | D11: =B11-C11 -> -13.67 | E11: =D11/B11 -> -0.06835 | G11: Total Spent | H11: =sum(C17) -> 8363.7167
A12: Travel | B12: 500 | C12: 500 | D12: =B12-C12 -> 0 | E12: =D12/B12 -> 0
A13: Gas | B13: 200 | C13: =sumif($B$20:$C$101,A13,$C$20:$C$101) -> 60 | D13: =B13-C13 -> 140 | E13: =D13/B13 -> 0.7 | G13: Recurring Expenses
A14: Health | B14: 0 | C14: =sumif($B$20:$C$101,A14,$C$20:$C$101) -> 0 | D14: =B14-C14 -> 0 | E14: =D14/B14 -> #DIV/0! | G14: Car Insurance
A15: Fun / Misc | B15: 300 | C15: =sumif($B$20:$C$101,A15,$C$20:$C$101) -> 2752.02 | D15: =B15-C15 -> -2452.02 | E15: =D15/B15 -> -8.1734
A16: Business School | B16: 0 | C16: =sumif($B$20:$C$101,A16,$C$20:$C$101) -> 0 | D16: =B16-C16 -> 0 | E16: =D16/B16 -> #DIV/0! | G16: Amount spent on Travel | H16: =SUMIF($B$20:$C$123,"Travel",$C$20:$C$123) -> 0
A17: Total | B17: =SUM(B6:B16) -> 4913.68 | C17: =SUM(C6:C16) -> 8363.7167 | D17: =SUM(D6:D15) -> -3450.0367 | E17: =D17/B17 -> -0.70212889 | G17: Amount in Travel Bank | H17: =500-SUMIF($B$20:$C$123,"Travel",$C$20:$C$123)+'May 2024'!H17 -> 859.45
A19: Date | B19: Category | C19: Spent | D19: Note
A20: Monthly | B20: Fixed | C20: 2900 | D20: Rent
A21: Monthly | B21: Fixed | C21: 40 | D21: Internet
A22: Monthly | B22: Fixed | C22: 85 | D22: Electric
A23: Monthly | B23: Fixed | C23: 42.62 | D23: Exercise
A24: Monthly | B24: Fixed | C24: 87 | D24: Gas
A25: Monthly | B25: Fixed | C25: =77/12 -> 6.4166667 | D25: Renters insurance
A26: Monthly | B26: Fixed | C26: 144 | D26: Car Insurance
A27: Monthly | B27: Fixed | C27: 2.87 | D27: Spotify - Martin
A28: Monthly | B28: Fixed | C28: 2.99 | D28: Google One
A29: Monthly | B29: Fixed | C29: 5.83 | D29: One Drive
A30: Monthly | B30: Fixed | C30: 6.25 | D30: MSFT
A31: Monthly | B31: Fixed | C31: 110 | D31: Phone
A34: 45444 | B34: Fun / Misc | C34: 56 | D34: Train to NY
A35: 45444 | B35: Fun / Misc | C35: 995 | D35: Hamilton Tickets
A36: 45445 | B36: Fun / Misc | C36: 14.7 | D36: Morristown Station Parking
A37: 45468 | B37: Fun / Misc | C37: 826 | D37: Croissant Bag
A38: 45472 | B38: Groceries | C38: 46.82 | D38: HMART
A39: 45473 | B39: Fun / Misc | C39: =196-28 -> 168 | D39: Train to NY
A40: 45473 | B40: Eating out | C40: 3.4 | D40: Mackyd
A41: 45470 | B41: Eating out | C41: 8.02 | D41: Coffee and Bagel
A42: 45445 | B42: Fun / Misc | C42: =8*2.9 -> 23.2 | D42: Subway
A43: 45445 | B43: Household Goods | C43: 111.32 | D43: J-Crew
A44: 45445 | B44: Household Goods | C44: 18.36 | D44: JCREW
A45: 45463 | B45: Eating out | C45: 8.2 | D45: Office Lunch
A46: 45462 | B46: Eating Out | C46: 17.05 | D46: Lunch
...

Sheet July 2024
A4: Monthly Spending | G4: Monthly Overview | J4: Expenses over Time
A5: Category | B5: Budgeted | C5: Amount Spent | D5: Amount Remaining | E5: % Remaining | G5: Income
A6: Fixed | B6: 2663.68 | C6: =sumif($B$20:$C$101,A6,$C$20:$C$101) -> 3366.0767 | D6: =B6-C6 -> -702.39667 | E6: =D6/B6 -> -0.26369409 | G6: Martin Paycheck | H6: =3080*2 -> 6160
A7: Utilities | B7: 0 | C7: =sumif($B$20:$C$101,A7,$C$20:$C$101) -> 0 | D7: =B7-C7 -> 0 | E7: =D7/B7 -> #DIV/0! | G7: Rachel Paycheck | H7: =3370*2 -> 6740
A8: Bills | B8: 250 | C8: =sumif($B$20:$C$101,A8,$C$20:$C$101) -> 0 | D8: =B8-C8 -> 250 | E8: =D8/B8 -> 1 | G8: Total | H8: =SUM(H6:H7) -> 12900
A9: Groceries | B9: 400 | C9: =sumif($B$20:$C$101,A9,$C$20:$C$101) -> 985.76333 | D9: =B9-C9 -> -585.76333 | E9: =D9/B9 -> -1.4644083
A10: Eating out | B10: 400 | C10: =sumif($B$20:$C$101,A10,$C$20:$C$101) -> 551.75333 | D10: =B10-C10 -> -151.75333 | E10: =D10/B10 -> -0.37938333 | G10: Monthly Expenses
A11: Household Goods | B11: 200 | C11: =sumif($B$20:$C$101,A11,$C$20:$C$101) -> 513.22 | D11: =B11-C11 -> -313.22 | E11: =D11/B11 -> -1.5661 | G11: Total Spent | H11: =sum(C17) -> 6564.97
A12: Travel | B12: 500 | C12: 500 | D12: =B12-C12 -> 0 | E12: =D12/B12 -> 0
A13: Gas | B13: 200 | C13: =sumif($B$20:$C$101,A13,$C$20:$C$101) -> 150.49 | D13: =B13-C13 -> 49.51 | E13: =D13/B13 -> 0.24755 | G13: Recurring Expenses
A14: Health | B14: 0 | C14: =sumif($B$20:$C$101,A14,$C$20:$C$101) -> 176.39 | D14: =B14-C14 -> -176.39 | E14: =D14/B14 -> #DIV/0! | G14: Car Insurance
A15: Fun / Misc | B15: 300 | C15: =sumif($B$20:$C$101,A15,$C$20:$C$101) -> 321.27667 | D15: =B15-C15 -> -21.276667 | E15: =D15/B15 -> -0.070922222
A16: Business School | B16: 0 | C16: =sumif($B$20:$C$101,A16,$C$20:$C$101) -> 0 | D16: =B16-C16 -> 0 | E16: =D16/B16 -> #DIV/0! | G16: Amount spent on Travel | H16: =SUMIF($B$20:$C$123,"Travel",$C$20:$C$123) -> 609.96
A17: Total | B17: =SUM(B6:B16) -> 4913.68 | C17: =SUM(C6:C16) -> 6564.97 | D17: =SUM(D6:D15) -> -1651.29 | E17: =D17/B17 -> -0.33605974 | G17: Amount in Travel Bank | H17: =500-SUMIF($B$20:$C$123,"Travel",$C$20:$C$123)+'June 2024'!H17 -> 749.49
A19: Date | B19: Category | C19: Spent | D19: Note
A20: Monthly | B20: Fixed | C20: 2900 | D20: Rent
A21: Monthly | B21: Fixed | C21: 40 | D21: Internet
A22: Monthly | B22: Fixed | C22: 85.61 | D22: Electric
A23: Monthly | B23: Fixed | C23: 42.62 | D23: Exercise
A24: Monthly | B24: Fixed | C24: 19.49 | D24: Gas
A25: Monthly | B25: Fixed | C25: =77/12 -> 6.4166667 | D25: Renters insurance
A26: Monthly | B26: Fixed | C26: 144 | D26: Car Insurance
A27: Monthly | B27: Fixed | C27: 2.87 | D27: Spotify - Martin
A28: Monthly | B28: Fixed | C28: 2.99 | D28: Google One
A29: Monthly | B29: Fixed | C29: 5.83 | D29: One Drive
A30: Monthly | B30: Fixed | C30: 6.25 | D30: MSFT
A31: Monthly | B31: Fixed | C31: 110 | D31: Phone
A34: 45474 | B34: Groceries | C34: 76.49 | D34: Costco
A35: 45475 | B35: Eating Out | C35: 7.84 | D35: BASF Lunch
A36: 45480 | B36: Health | C36: 56.39 | D36: Duke Health Visit
A37: 45479 | B37: Household Goods | C37: 19.26 | D37: Hygeiene
A38: 45474 | B38: Eating out | C38: 1.6 | D38: Costo dog
A39: 45479 | B39: Eating out | C39: 23.61 | D39: Chick Fil a
A40: 45477 | B40: Eating out | C40: 24.52 | D40: Panda Express
A41: 45479 | B41: Household Goods | C41: 6 | D41: Paper
A42: 45481 | B42: Gas | C42: 43 | D42: Quickcheck
A43: 45486 | B43: Fun / Misc | C43: 10.5 | D43: EWR parking
A44: 45487 | B44: Eating out | C44: 21 | D44: Pizza
A45: 45487 | B45: Fun / Misc | C45: =2.9*6 -> 17.4 | D45: MTA
A46: 45491 | B46: Fun / Misc | C46: 60 | D46: Golf with matt
...

Sheet Aug 2024
A4: Monthly Spending | G4: Monthly Overview | J4: Expenses over Time
A5: Category | B5: Budgeted | C5: Amount Spent | D5: Amount Remaining | E5: % Remaining | G5: Income
A6: Fixed | B6: 2663.68 | C6: =sumif($B$20:$C$101,A6,$C$20:$C$101) -> 4848.4767 | D6: =B6-C6 -> -2184.7967 | E6: =D6/B6 -> -0.82021739 | G6: Martin Paycheck | H6: =3080*2 -> 6160
A7: Utilities | B7: 0 | C7: =sumif($B$20:$C$101,A7,$C$20:$C$101) -> 0 | D7: =B7-C7 -> 0 | E7: =D7/B7 -> #DIV/0! | G7: Rachel Paycheck | H7: =3370*2 -> 6740
A8: Bills | B8: 250 | C8: =sumif($B$20:$C$101,A8,$C$20:$C$101) -> 155.65 | D8: =B8-C8 -> 94.35 | E8: =D8/B8 -> 0.3774 | G8: Total | H8: =SUM(H6:H7) -> 12900
A9: Groceries | B9: 400 | C9: =sumif($B$20:$C$101,A9,$C$20:$C$101) -> 1085.31 | D9: =B9-C9 -> -685.31 | E9: =D9/B9 -> -1.713275
A10: Eating out | B10: 400 | C10: =sumif($B$20:$C$101,A10,$C$20:$C$101) -> 695.20286 | D10: =B10-C10 -> -295.20286 | E10: =D10/B10 -> -0.73800714 | G10: Monthly Expenses
A11: Household Goods | B11: 200 | C11: =sumif($B$20:$C$101,A11,$C$20:$C$101) -> 440.07 | D11: =B11-C11 -> -240.07 | E11: =D11/B11 -> -1.20035 | G11: Total Spent | H11: =sum(C17) -> 8643.1595
A12: Travel | B12: 500 | C12: 500 | D12: =B12-C12 -> 0 | E12: =D12/B12 -> 0
A13: Gas | B13: 200 | C13: =sumif($B$20:$C$101,A13,$C$20:$C$101) -> 134.8 | D13: =B13-C13 -> 65.2 | E13: =D13/B13 -> 0.326 | G13: Recurring Expenses
A14: Health | B14: 0 | C14: =sumif($B$20:$C$101,A14,$C$20:$C$101) -> 386.22 | D14: =B14-C14 -> -386.22 | E14: =D14/B14 -> #DIV/0! | G14: Car Insurance
A15: Fun / Misc | B15: 300 | C15: =sumif($B$20:$C$101,A15,$C$20:$C$101) -> 397.43 | D15: =B15-C15 -> -97.43 | E15: =D15/B15 -> -0.32476667
A16: Business School | B16: 0 | C16: =sumif($B$20:$C$101,A16,$C$20:$C$101) -> 0 | D16: =B16-C16 -> 0 | E16: =D16/B16 -> #DIV/0! | G16: Amount spent on Travel | H16: =SUMIF($B$20:$C$123,"Travel",$C$20:$C$123) -> 618
A17: Total | B17: =SUM(B6:B16) -> 4913.68 | C17: =SUM(C6:C16) -> 8643.1595 | D17: =SUM(D6:D15) -> -3729.4795 | E17: =D17/B17 -> -0.75899927 | G17: Amount in Travel Bank | H17: =500-SUMIF($B$20:$C$123,"Travel",$C$20:$C$123)+'July 2024'!H17 -> 631.49
A19: Date | B19: Category | C19: Spent | D19: Note
A20: Monthly | B20: Fixed | C20: =2900+1476 -> 4376 | D20: Rent
A21: Monthly | B21: Fixed | C21: 40 | D21: Internet
A22: Monthly | B22: Fixed | C22: 89 | D22: Electric
A23: Monthly | B23: Fixed | C23: 42.62 | D23: Exercise
A24: Monthly | B24: Fixed | C24: 20.5 | D24: Gas
A25: Monthly | B25: Fixed | C25: =77/12 -> 6.4166667 | D25: Renters insurance
A26: Monthly | B26: Fixed | C26: 144 | D26: Car Insurance
A27: Monthly | B27: Fixed | C27: 2.87 | D27: Spotify - Martin
A28: Monthly | B28: Fixed | C28: 2.99 | D28: Google One
A29: Monthly | B29: Fixed | C29: 5.83 | D29: One Drive
A30: Monthly | B30: Fixed | C30: 6.25 | D30: MSFT
A31: Monthly | B31: Fixed | C31: 112 | D31: Phone
A34: 45506 | B34: Fun / Misc | C34: 10.75 | D34: Spothero Parking
A35: 45507 | B35: Groceries | C35: 26.67 | D35: Whole Foods
A36: 45507 | B36: Gas | C36: 59.8 | D36: Gas
A37: 45507 | B37: Eating out | C37: 7.47 | D37: Mcdonalds
A38: 45507 | B38: Household Goods | C38: 5.99 | D38: Amazon
A39: 45509 | B39: Household Goods | C39: 3.19 | D39: Best Buy
A40: 45509 | B40: Eating out | C40: 4.47 | D40: Mcdonalds
A41: 45512 | B41: Eating out | C41: 3.47 | D41: Chick fil a
A42: 45514 | B42: Eating out | C42: 14.49 | D42: Mcdonalds
A44: 45515 | B44: Health | C44: 99.1 | D44: Vision
A45: 45505 | B45: Health | C45: 179.12 | D45: Glasses
A46: 45515 | B46: Groceries | C46: 85.58 | D46: Costco
... A51: 45513 | B51: Travel | C51: 540 | D51: Delta Airlines
...

Sheet Sept 2024
A4: Monthly Spending | G4: Monthly Overview | J4: Expenses over Time
A5: Category | B5: Budgeted | C5: Amount Spent | D5: Amount Remaining | E5: % Remaining | G5: Income
A6: Fixed | B6: 2663.68 | C6: =sumif($B$20:$C$102,A6,$C$20:$C$102) -> 4747.0267 | D6: =B6-C6 -> -2083.3467 | E6: =D6/B6 -> -0.78213099 | G6: Martin Paycheck | H6: 5000
A7: Utilities | B7: 0 | C7: =sumif($B$20:$C$102,A7,$C$20:$C$102) -> 0 | D7: =B7-C7 -> 0 | E7: =D7/B7 -> #DIV/0! | G7: Rachel Paycheck | H7: 4200
A8: Bills | B8: 250 | C8: =sumif($B$20:$C$102,A8,$C$20:$C$102) -> 11 | D8: =B8-C8 -> 239 | E8: =D8/B8 -> 0.956 | G8: Total | H8: =SUM(H6:H7) -> 9200
A9: Groceries | B9: 400 | C9: =sumif($B$20:$C$102,A9,$C$20:$C$102) -> 1281.1 | D9: =B9-C9 -> -881.1 | E9: =D9/B9 -> -2.20275
A10: Eating out | B10: 400 | C10: =sumif($B$20:$C$102,A10,$C$20:$C$102) -> 673.3 | D10: =B10-C10 -> -273.3 | E10: =D10/B10 -> -0.68325 | G10: Monthly Expenses
A11: Household Goods | B11: 200 | C11: =sumif($B$20:$C$102,A11,$C$20:$C$102) -> 166.77 | D11: =B11-C11 -> 33.23 | E11: =D11/B11 -> 0.16615 | G11: Total Spent | H11: =sum(C17) -> 8077.7067
A12: Travel | B12: 500 | C12: 500 | D12: =B12-C12 -> 0 | E12: =D12/B12 -> 0
A13: Gas | B13: 200 | C13: =sumif($B$20:$C$102,A13,$C$20:$C$102) -> 0 | D13: =B13-C13 -> 200 | E13: =D13/B13 -> 1 | G13: Recurring Expenses
A14: Health | B14: 0 | C14: =sumif($B$20:$C$102,A14,$C$20:$C$102) -> 93.55 | D14: =B14-C14 -> -93.55 | E14: =D14/B14 -> #DIV/0! | G14: Car Insurance
A15: Fun / Misc | B15: 300 | C15: =sumif($B$20:$C$102,A15,$C$20:$C$102) -> 319.96 | D15: =B15-C15 -> -19.96 | E15: =D15/B15 -> -0.066533333
A16: Business School | B16: 0 | C16: =sumif($B$20:$C$102,A16,$C$20:$C$102) -> 285 | D16: =B16-C16 -> -285 | E16: =D16/B16 -> #DIV/0! | G16: Amount spent on Travel | H16: =SUMIF($B$20:$C$174,"Travel",$C$20:$C$174) -> 556.98
A17: Total | B17: =SUM(B6:B16) -> 4913.68 | C17: =SUM(C6:C16) -> 8077.7067 | D17: =SUM(D6:D15) -> -2879.0267 | E17: =D17/B17 -> -0.58592067 | G17: Amount in Travel Bank | H17: =500-SUMIF($B$20:$C$174,"Travel",$C$20:$C$174)+'April 2024'!H17 -> 446.26
A19: Date | B19: Category | C19: Spent | D19: Note
A20: Monthly | B20: Fixed | C20: =2900+1476 -> 4376 | D20: Rent
A21: Monthly | B21: Fixed | C21: 40 | D21: Internet
A22: Monthly | B22: Fixed | C22: 40 | D22: Electric
A23: Monthly | B23: Fixed | C23: 42.62 | D23: Exercise
A24: Monthly | B24: Fixed | C24: 16.55 | D24: Gas | G24: Credit balance (9/29)
A25: Monthly | B25: Fixed | C25: =77/12 -> 6.4166667 | D25: Renters insurance | F25: RSB Chase | G25: =8.62+3758.03 -> 3766.65 | H25: 6k from 4668 card
A26: Monthly | B26: Fixed | C26: =585/6 -> 97.5 | D26: Car Insurance | F26: RSB Amex | G26: 0
A27: Monthly | B27: Fixed | C27: 2.87 | D27: Spotify - Martin | F27: RSB Barclay | G27: 965.33
A28: Monthly | B28: Fixed | C28: 2.99 | D28: Google One | F28: ML Chase | G28: =274.97+19.17+184.41+1077.59+1829.28 -> 3385.42
A29: Monthly | B29: Fixed | C29: 5.83 | D29: One Drive | F29: ML Amex | G29: =27.87 -> 27.87 | H29: only amex gold
A30: Monthly | B30: Fixed | C30: 6.25 | D30: MSFT | F30: ML Barclay | G30: 1388.4
A31: Monthly | B31: Fixed | C31: 110 | D31: Phone | F31: TOTAL | G31: =SUM(G25:G30) -> 9533.67
F32: Rent | G32: 2900
G33: 8000
A34: 45555 | B34: Eating out | C34: 42.44 | D34: Dinner & Drinks | E34: ML
A35: 45537 | B35: Fun / Misc | C35: 25 | D35: Danielle Wedding Gift
A36: 45544 | B36: Fun / Misc | C36: 16 | D36: SO event
A37: 45538 | B37: Household Goods | C37: 130 | D37: Amazon
A38: 45541 | B38: Household Goods | C38: 5 | D38: Laundry
A39: 45540 | B39: Eating out | C39: =10.11*2 -> 20.22 | D39: Chipotle
A40: 45540 | B40: Health | C40: 5.88 | D40: Walgreens
A41: 45540 | B41: Fun / Misc | C41: 4.5 | D41: Blue bike
A42: 45540 | B42: Eating out | C42: 15.3 | D42: Drinks
A43: 45540 | B43: Fun / Misc | C43: 4.87 | D43: Pirate Ship
A44: 45539 | B44: Fun / Misc | C44: 30.92 | D44: Going
...

Sheet Oct 2024
A4: Monthly Spending | G4: Monthly Overview | J4: Expenses over Time
A5: Category | B5: Budgeted | C5: Amount Spent | D5: Amount Remaining | E5: % Remaining | G5: Income
A6: Fixed | B6: 2663.68 | C6: =sumif($B$20:$C$501,A6,$C$20:$C$501) -> 4730.4767 | D6: =B6-C6 -> -2066.7967 | E6: =D6/B6 -> -0.77591778 | G6: Martin Paycheck | H6: 0
A7: Utilities | B7: 0 | C7: =sumif($B$20:$C$501,A7,$C$20:$C$501) -> 0 | D7: =B7-C7 -> 0 | E7: =D7/B7 -> #DIV/0! | G7: Rachel Paycheck | H7: 4200
A8: Bills | B8: 250 | C8: =sumif($B$20:$C$501,A8,$C$20:$C$501) -> 217.3 | D8: =B8-C8 -> 32.7 | E8: =D8/B8 -> 0.1308 | G8: Total | H8: =SUM(H6:H7) -> 4200
A9: Groceries | B9: 400 | C9: =sumif($B$20:$C$501,A9,$C$20:$C$501) -> 647.84 | D9: =B9-C9 -> -247.84 | E9: =D9/B9 -> -0.6196
A10: Eating out | B10: 400 | C10: =sumif($B$20:$C$501,A10,$C$20:$C$501) -> 648.9 | D10: =B10-C10 -> -248.9 | E10: =D10/B10 -> -0.62225 | G10: Monthly Expenses
A11: Household Goods | B11: 200 | C11: =sumif($B$20:$C$501,A11,$C$20:$C$501) -> 818.45 | D11: =B11-C11 -> -618.45 | E11: =D11/B11 -> -3.09225 | G11: Total Spent | H11: =sum(C17) -> 8794.2167
A12: Travel | B12: 500 | C12: =sumif($B$20:$C$501,A12,$C$20:$C$501) -> 244.12 | D12: =B12-C12 -> 255.88 | E12: =D12/B12 -> 0.51176
